Traceback (most recent call last):
  File "/home/codespace/.local/lib/python3.12/site-packages/jupyter_core/utils/__init__.py", line 154, in wrapped
    asyncio.get_running_loop()
RuntimeError: no running event loop

During handling of the above exception, another exception occurred:

Traceback (most recent call last):
  File "/usr/local/python/3.12.1/lib/python3.12/site-packages/jupyter_cache/executors/utils.py", line 58, in single_nb_execution
    executenb(
  File "/home/codespace/.local/lib/python3.12/site-packages/nbclient/client.py", line 1319, in execute
    return NotebookClient(nb=nb, resources=resources, km=km, **kwargs).execute()
           ^^^^^^^^^^^^^^^^^^^^^^^^^^^^^^^^^^^^^^^^^^^^^^^^^^^^^^^^^^^^^^^^^^^^^
  File "/home/codespace/.local/lib/python3.12/site-packages/jupyter_core/utils/__init__.py", line 158, in wrapped
    return loop.run_until_complete(inner)
           ^^^^^^^^^^^^^^^^^^^^^^^^^^^^^^
  File "/usr/local/python/3.12.1/lib/python3.12/asyncio/base_events.py", line 684, in run_until_complete
    return future.result()
           ^^^^^^^^^^^^^^^
  File "/home/codespace/.local/lib/python3.12/site-packages/nbclient/client.py", line 709, in async_execute
    await self.async_execute_cell(
  File "/home/codespace/.local/lib/python3.12/site-packages/nbclient/client.py", line 1062, in async_execute_cell
    await self._check_raise_for_error(cell, cell_index, exec_reply)
  File "/home/codespace/.local/lib/python3.12/site-packages/nbclient/client.py", line 918, in _check_raise_for_error
    raise CellExecutionError.from_cell_and_msg(cell, exec_reply_content)
nbclient.exceptions.CellExecutionError: An error occurred while executing the following cell:
------------------
df = pd.read_csv('ecoli.data')
print("Isi tabel ecoli:\n")
print(df.head())
------------------


[31m---------------------------------------------------------------------------[39m
[31mNameError[39m                                 Traceback (most recent call last)
[36mCell[39m[36m [39m[32mIn[1][39m[32m, line 1[39m
[32m----> [39m[32m1[39m df = [43mpd[49m.read_csv([33m'[39m[33mecoli.data[39m[33m'[39m)
[32m      2[39m [38;5;28mprint[39m([33m"[39m[33mIsi tabel ecoli:[39m[38;5;130;01m\n[39;00m[33m"[39m)
[32m      3[39m [38;5;28mprint[39m(df.head())

[31mNameError[39m: name 'pd' is not defined

